<sdf version='1.7'>
  <world name='default'>
    <light name='sun' type='directional'>
      <cast_shadows>1</cast_shadows>
      <pose>0 0 10 0 -0 0</pose>
      <diffuse>0.8 0.8 0.8 1</diffuse>
      <specular>0.2 0.2 0.2 1</specular>
      <attenuation>
        <range>1000</range>
        <constant>0.9</constant>
        <linear>0.01</linear>
        <quadratic>0.001</quadratic>
      </attenuation>
      <direction>-0.5 0.1 -0.9</direction>
      <spot>
        <inner_angle>0</inner_angle>
        <outer_angle>0</outer_angle>
        <falloff>0</falloff>
      </spot>
    </light>
    <gravity>0 0 -9.8</gravity>
    <magnetic_field>6e-06 2.3e-05 -4.2e-05</magnetic_field>
    <atmosphere type='adiabatic'/>
    <physics type='ode'>
      <max_step_size>0.001</max_step_size>
      <real_time_factor>1</real_time_factor>
      <real_time_update_rate>1000</real_time_update_rate>
    </physics>
    <scene>
      <ambient>0.4 0.4 0.4 1</ambient>
      <background>0.7 0.7 0.7 1</background>
      <shadows>1</shadows>
    </scene>
    <wind/>
    <spherical_coordinates>
      <surface_model>EARTH_WGS84</surface_model>
      <latitude_deg>0</latitude_deg>
      <longitude_deg>0</longitude_deg>
      <elevation>0</elevation>
      <heading_deg>0</heading_deg>
    </spherical_coordinates>
    <model name='garbage_robot'>
      <link name='base_footprint'>
        <inertial>
          <pose>0.319984 0.004899 0.421958 0 -0 0</pose>
          <mass>246.679</mass>
          <inertia>
            <ixx>45.9334</ixx>
            <ixy>-0.463424</ixy>
            <ixz>-10.427</ixz>
            <iyy>117.969</iyy>
            <iyz>-0.385502</iyz>
            <izz>130.914</izz>
          </inertia>
        </inertial>
        <collision name='base_footprint_fixed_joint_lump__base_link_collision'>
          <pose>0 0 0 0 -0 0</pose>
          <geometry>
            <mesh>
              <scale>0.001 0.001 0.001</scale>
              <uri>/home/deepak/catkin_ws/src/garbage_robot_description/meshes/base_link.stl</uri>
            </mesh>
          </geometry>
          <surface>
            <contact>
              <ode/>
            </contact>
            <friction>
              <ode>
                <mu>0.2</mu>
                <mu2>0.2</mu2>
              </ode>
              <torsional>
                <ode/>
              </torsional>
            </friction>
            <bounce/>
          </surface>
          <max_contacts>10</max_contacts>
        </collision>
        <collision name='base_footprint_fixed_joint_lump__front_cam_1_collision_1'>
          <pose>0 0 0 0 -0 0</pose>
          <geometry>
            <mesh>
              <scale>0.001 0.001 0.001</scale>
              <uri>/home/deepak/catkin_ws/src/garbage_robot_description/meshes/front_cam_1.stl</uri>
            </mesh>
          </geometry>
          <surface>
            <contact>
              <ode/>
            </contact>
            <friction>
              <ode>
                <mu>0.2</mu>
                <mu2>0.2</mu2>
              </ode>
              <torsional>
                <ode/>
              </torsional>
            </friction>
            <bounce/>
          </surface>
          <max_contacts>10</max_contacts>
        </collision>
        <collision name='base_footprint_fixed_joint_lump__imu_link_1_collision_2'>
          <pose>0 0 0 0 -0 0</pose>
          <geometry>
            <mesh>
              <scale>0.001 0.001 0.001</scale>
              <uri>/home/deepak/catkin_ws/src/garbage_robot_description/meshes/imu_link_1.stl</uri>
            </mesh>
          </geometry>
          <surface>
            <contact>
              <ode/>
            </contact>
            <friction>
              <ode>
                <mu>0.2</mu>
                <mu2>0.2</mu2>
              </ode>
              <torsional>
                <ode/>
              </torsional>
            </friction>
            <bounce/>
          </surface>
          <max_contacts>10</max_contacts>
        </collision>
        <collision name='base_footprint_fixed_joint_lump__side_cam_1_collision_3'>
          <pose>0 0 0 0 -0 0</pose>
          <geometry>
            <mesh>
              <scale>0.001 0.001 0.001</scale>
              <uri>/home/deepak/catkin_ws/src/garbage_robot_description/meshes/side_cam_1.stl</uri>
            </mesh>
          </geometry>
          <surface>
            <contact>
              <ode/>
            </contact>
            <friction>
              <ode>
                <mu>0.2</mu>
                <mu2>0.2</mu2>
              </ode>
              <torsional>
                <ode/>
              </torsional>
            </friction>
            <bounce/>
          </surface>
          <max_contacts>10</max_contacts>
        </collision>
        <collision name='base_footprint_fixed_joint_lump__container_1_collision_4'>
          <pose>0 0 0 0 -0 0</pose>
          <geometry>
            <mesh>
              <scale>0.001 0.001 0.001</scale>
              <uri>/home/deepak/catkin_ws/src/garbage_robot_description/meshes/container_1.stl</uri>
            </mesh>
          </geometry>
          <surface>
            <contact>
              <ode/>
            </contact>
            <friction>
              <ode>
                <mu>0.2</mu>
                <mu2>0.2</mu2>
              </ode>
              <torsional>
                <ode/>
              </torsional>
            </friction>
            <bounce/>
          </surface>
          <max_contacts>10</max_contacts>
        </collision>
        <visual name='base_footprint_fixed_joint_lump__base_link_visual'>
          <pose>0 0 0 0 -0 0</pose>
          <geometry>
            <mesh>
              <scale>0.001 0.001 0.001</scale>
              <uri>/home/deepak/catkin_ws/src/garbage_robot_description/meshes/base_link.stl</uri>
            </mesh>
          </geometry>
          <material>
            <script>
              <name>Gazebo/Green</name>
              <uri>file://media/materials/scripts/gazebo.material</uri>
            </script>
          </material>
        </visual>
        <visual name='base_footprint_fixed_joint_lump__front_cam_1_visual_1'>
          <pose>0 0 0 0 -0 0</pose>
          <geometry>
            <mesh>
              <scale>0.001 0.001 0.001</scale>
              <uri>/home/deepak/catkin_ws/src/garbage_robot_description/meshes/front_cam_1.stl</uri>
            </mesh>
          </geometry>
          <material>
            <script>
              <name>Gazebo/Green</name>
              <uri>file://media/materials/scripts/gazebo.material</uri>
            </script>
          </material>
        </visual>
        <visual name='base_footprint_fixed_joint_lump__imu_link_1_visual_2'>
          <pose>0 0 0 0 -0 0</pose>
          <geometry>
            <mesh>
              <scale>0.001 0.001 0.001</scale>
              <uri>/home/deepak/catkin_ws/src/garbage_robot_description/meshes/imu_link_1.stl</uri>
            </mesh>
          </geometry>
          <material>
            <script>
              <name>Gazebo/Green</name>
              <uri>file://media/materials/scripts/gazebo.material</uri>
            </script>
          </material>
        </visual>
        <visual name='base_footprint_fixed_joint_lump__side_cam_1_visual_3'>
          <pose>0 0 0 0 -0 0</pose>
          <geometry>
            <mesh>
              <scale>0.001 0.001 0.001</scale>
              <uri>/home/deepak/catkin_ws/src/garbage_robot_description/meshes/side_cam_1.stl</uri>
            </mesh>
          </geometry>
          <material>
            <script>
              <name>Gazebo/Green</name>
              <uri>file://media/materials/scripts/gazebo.material</uri>
            </script>
          </material>
        </visual>
        <visual name='base_footprint_fixed_joint_lump__container_1_visual_4'>
          <pose>0 0 0 0 -0 0</pose>
          <geometry>
            <mesh>
              <scale>0.001 0.001 0.001</scale>
              <uri>/home/deepak/catkin_ws/src/garbage_robot_description/meshes/container_1.stl</uri>
            </mesh>
          </geometry>
          <material>
            <script>
              <name>Gazebo/Red</name>
              <uri>file://media/materials/scripts/gazebo.material</uri>
            </script>
          </material>
        </visual>
        <gravity>1</gravity>
        <gravity>1</gravity>
        <sensor name='imu_sensor' type='imu'>
          <always_on>1</always_on>
          <update_rate>100</update_rate>
          <visualize>1</visualize>
          <topic>__default_topic__</topic>
          <plugin name='imu_plugin' filename='libgazebo_ros_imu_sensor.so'>
            <topicName>imu_data</topicName>
            <bodyName>imu_link</bodyName>
            <updateRateHZ>10.0</updateRateHZ>
            <gaussianNoise>0.0</gaussianNoise>
            <xyzOffset>0 0 0</xyzOffset>
            <rpyOffset>0 0 0</rpyOffset>
            <frameName>imu_link_1</frameName>
            <initialOrientationAsReference>0</initialOrientationAsReference>
            <robotNamespace>/</robotNamespace>
          </plugin>
          <pose>0.435 0 0.255 0 -0 0</pose>
          <imu/>
        </sensor>
        <self_collide>1</self_collide>
        <enable_wind>0</enable_wind>
        <kinematic>0</kinematic>
      </link>
      <joint name='Slider' type='prismatic'>
        <pose relative_to='base_footprint'>-0.35 0.1 0.945 0 -0 0</pose>
        <parent>base_footprint</parent>
        <child>link1_1</child>
        <axis>
          <xyz>0 1 0</xyz>
          <limit>
            <lower>0</lower>
            <upper>0.3</upper>
            <effort>100</effort>
            <velocity>0.5</velocity>
          </limit>
          <dynamics>
            <spring_reference>0</spring_reference>
            <spring_stiffness>0</spring_stiffness>
          </dynamics>
        </axis>
      </joint>
      <link name='link1_1'>
        <pose relative_to='Slider'>0 0 0 0 -0 0</pose>
        <inertial>
          <pose>0.9 0.082003 -0.12642 0 -0 0</pose>
          <mass>2.14607</mass>
          <inertia>
            <ixx>0.018306</ixx>
            <ixy>0</ixy>
            <ixz>0</ixz>
            <iyy>0.011609</iyy>
            <iyz>0.00497</iyz>
            <izz>0.007961</izz>
          </inertia>
        </inertial>
        <collision name='link1_1_collision'>
          <pose>0.35 -0.1 -0.945 0 -0 0</pose>
          <geometry>
            <mesh>
              <scale>0.001 0.001 0.001</scale>
              <uri>/home/deepak/catkin_ws/src/garbage_robot_description/meshes/link1_1.stl</uri>
            </mesh>
          </geometry>
          <surface>
            <contact>
              <ode/>
            </contact>
            <friction>
              <ode>
                <mu>0.2</mu>
                <mu2>0.2</mu2>
              </ode>
              <torsional>
                <ode/>
              </torsional>
            </friction>
            <bounce/>
          </surface>
          <max_contacts>10</max_contacts>
        </collision>
        <visual name='link1_1_visual'>
          <pose>0.35 -0.1 -0.945 0 -0 0</pose>
          <geometry>
            <mesh>
              <scale>0.001 0.001 0.001</scale>
              <uri>/home/deepak/catkin_ws/src/garbage_robot_description/meshes/link1_1.stl</uri>
            </mesh>
          </geometry>
          <material>
            <script>
              <name>Gazebo/Orange</name>
              <uri>file://media/materials/scripts/gazebo.material</uri>
            </script>
          </material>
        </visual>
        <self_collide>1</self_collide>
        <enable_wind>0</enable_wind>
        <kinematic>0</kinematic>
      </link>
      <joint name='arm_joint' type='revolute'>
        <pose relative_to='link1_1'>0.92 0.205 -0.189 0 -0 0</pose>
        <parent>link1_1</parent>
        <child>LINK2_1</child>
        <axis>
          <xyz>1 0 0</xyz>
          <limit>
            <lower>-3.14</lower>
            <upper>3.14</upper>
            <effort>100</effort>
            <velocity>0.5</velocity>
          </limit>
          <dynamics>
            <spring_reference>0</spring_reference>
            <spring_stiffness>0</spring_stiffness>
          </dynamics>
        </axis>
      </joint>
      <link name='LINK2_1'>
        <pose relative_to='arm_joint'>0 0 0 0 -0 0</pose>
        <inertial>
          <pose>-0.106948 0.109925 -0.361717 0 -0 0</pose>
          <mass>4.17118</mass>
          <inertia>
            <ixx>0.144545</ixx>
            <ixy>0.052615</ixy>
            <ixz>-0.035282</ixz>
            <iyy>0.209347</iyy>
            <iyz>0.044606</iyz>
            <izz>0.175506</izz>
          </inertia>
        </inertial>
        <collision name='LINK2_1_collision'>
          <pose>-0.57 -0.305 -0.756 0 -0 0</pose>
          <geometry>
            <mesh>
              <scale>0.001 0.001 0.001</scale>
              <uri>/home/deepak/catkin_ws/src/garbage_robot_description/meshes/LINK2_1.stl</uri>
            </mesh>
          </geometry>
          <surface>
            <contact>
              <ode/>
            </contact>
            <friction>
              <ode>
                <mu>0.2</mu>
                <mu2>0.2</mu2>
              </ode>
              <torsional>
                <ode/>
              </torsional>
            </friction>
            <bounce/>
          </surface>
          <max_contacts>10</max_contacts>
        </collision>
        <visual name='LINK2_1_visual'>
          <pose>-0.57 -0.305 -0.756 0 -0 0</pose>
          <geometry>
            <mesh>
              <scale>0.001 0.001 0.001</scale>
              <uri>/home/deepak/catkin_ws/src/garbage_robot_description/meshes/LINK2_1.stl</uri>
            </mesh>
          </geometry>
          <material>
            <script>
              <name>Gazebo/Orange</name>
              <uri>file://media/materials/scripts/gazebo.material</uri>
            </script>
          </material>
        </visual>
        <self_collide>1</self_collide>
        <enable_wind>0</enable_wind>
        <kinematic>0</kinematic>
      </link>
      <joint name='gripper1_joint' type='revolute'>
        <pose relative_to='LINK2_1'>-0.621 0.255 -0.475 0 -0 0</pose>
        <parent>LINK2_1</parent>
        <child>gripper1_1</child>
        <axis>
          <xyz>0 0 -1</xyz>
          <limit>
            <lower>-3.14</lower>
            <upper>3.14</upper>
            <effort>100</effort>
            <velocity>0.5</velocity>
          </limit>
          <dynamics>
            <spring_reference>0</spring_reference>
            <spring_stiffness>0</spring_stiffness>
          </dynamics>
        </axis>
      </joint>
      <link name='gripper1_1'>
        <pose relative_to='gripper1_joint'>0 0 0 0 -0 0</pose>
        <inertial>
          <pose>0.258664 0.010474 -0.005 0 -0 0</pose>
          <mass>1.79622</mass>
          <inertia>
            <ixx>0.003042</ixx>
            <ixy>-0.005052</ixy>
            <ixz>0</ixz>
            <iyy>0.040386</iyy>
            <iyz>0</iyz>
            <izz>0.043398</izz>
          </inertia>
        </inertial>
        <collision name='gripper1_1_collision'>
          <pose>0.051 -0.56 -0.281 0 -0 0</pose>
          <geometry>
            <mesh>
              <scale>0.001 0.001 0.001</scale>
              <uri>/home/deepak/catkin_ws/src/garbage_robot_description/meshes/gripper1_1.stl</uri>
            </mesh>
          </geometry>
          <surface>
            <contact>
              <ode/>
            </contact>
            <friction>
              <ode>
                <mu>0.2</mu>
                <mu2>0.2</mu2>
              </ode>
              <torsional>
                <ode/>
              </torsional>
            </friction>
            <bounce/>
          </surface>
          <max_contacts>10</max_contacts>
        </collision>
        <visual name='gripper1_1_visual'>
          <pose>0.051 -0.56 -0.281 0 -0 0</pose>
          <geometry>
            <mesh>
              <scale>0.001 0.001 0.001</scale>
              <uri>/home/deepak/catkin_ws/src/garbage_robot_description/meshes/gripper1_1.stl</uri>
            </mesh>
          </geometry>
          <material>
            <script>
              <name>Gazebo/Orange</name>
              <uri>file://media/materials/scripts/gazebo.material</uri>
            </script>
          </material>
        </visual>
        <self_collide>1</self_collide>
        <enable_wind>0</enable_wind>
        <kinematic>0</kinematic>
      </link>
      <joint name='gripper2_joint' type='revolute'>
        <pose relative_to='LINK2_1'>-0.621 0.255 -0.495 0 -0 0</pose>
        <parent>LINK2_1</parent>
        <child>gripper2_1</child>
        <axis>
          <xyz>0 0 -1</xyz>
          <limit>
            <lower>-3.14</lower>
            <upper>3.14</upper>
            <effort>100</effort>
            <velocity>0.5</velocity>
          </limit>
          <dynamics>
            <spring_reference>0</spring_reference>
            <spring_stiffness>0</spring_stiffness>
          </dynamics>
        </axis>
      </joint>
      <link name='gripper2_1'>
        <pose relative_to='gripper2_joint'>0 0 0 0 -0 0</pose>
        <inertial>
          <pose>-0.258664 0.010474 -0.005 0 -0 0</pose>
          <mass>1.79622</mass>
          <inertia>
            <ixx>0.003042</ixx>
            <ixy>0.005052</ixy>
            <ixz>0</ixz>
            <iyy>0.040386</iyy>
            <iyz>0</iyz>
            <izz>0.043398</izz>
          </inertia>
        </inertial>
        <collision name='gripper2_1_collision'>
          <pose>0.051 -0.56 -0.281 0 -0 0</pose>
          <geometry>
            <mesh>
              <scale>0.001 0.001 0.001</scale>
              <uri>/home/deepak/catkin_ws/src/garbage_robot_description/meshes/gripper2_1.stl</uri>
            </mesh>
          </geometry>
          <surface>
            <contact>
              <ode/>
            </contact>
            <friction>
              <ode>
                <mu>0.2</mu>
                <mu2>0.2</mu2>
              </ode>
              <torsional>
                <ode/>
              </torsional>
            </friction>
            <bounce/>
          </surface>
          <max_contacts>10</max_contacts>
        </collision>
        <visual name='gripper2_1_visual'>
          <pose>0.051 -0.56 -0.281 0 -0 0</pose>
          <geometry>
            <mesh>
              <scale>0.001 0.001 0.001</scale>
              <uri>/home/deepak/catkin_ws/src/garbage_robot_description/meshes/gripper2_1.stl</uri>
            </mesh>
          </geometry>
          <material>
            <script>
              <name>Gazebo/Orange</name>
              <uri>file://media/materials/scripts/gazebo.material</uri>
            </script>
          </material>
        </visual>
        <self_collide>1</self_collide>
        <enable_wind>0</enable_wind>
        <kinematic>0</kinematic>
      </link>
      <joint name='back_left_joint' type='revolute'>
        <pose relative_to='base_footprint'>-0.9 0.6 0.195 0 -0 0</pose>
        <parent>base_footprint</parent>
        <child>back_wheel_L_1</child>
        <axis>
          <xyz>0 1 0</xyz>
          <limit>
            <lower>-1e+16</lower>
            <upper>1e+16</upper>
          </limit>
          <dynamics>
            <spring_reference>0</spring_reference>
            <spring_stiffness>0</spring_stiffness>
          </dynamics>
        </axis>
      </joint>
      <link name='back_wheel_L_1'>
        <pose relative_to='back_left_joint'>0 0 0 0 -0 0</pose>
        <inertial>
          <pose>-0 0.005 0 0 -0 0</pose>
          <mass>48.0694</mass>
          <inertia>
            <ixx>0.430714</ixx>
            <ixy>0</ixy>
            <ixz>0</ixz>
            <iyy>0.78997</iyy>
            <iyz>0</iyz>
            <izz>0.430714</izz>
          </inertia>
        </inertial>
        <collision name='back_wheel_L_1_collision'>
          <pose>0.9 -0.6 -0.195 0 -0 0</pose>
          <geometry>
            <mesh>
              <scale>0.001 0.001 0.001</scale>
              <uri>/home/deepak/catkin_ws/src/garbage_robot_description/meshes/back_wheel_L_1.stl</uri>
            </mesh>
          </geometry>
          <surface>
            <contact>
              <ode/>
            </contact>
            <friction>
              <ode>
                <mu>100</mu>
                <mu2>100</mu2>
              </ode>
              <torsional>
                <ode/>
              </torsional>
            </friction>
            <bounce/>
          </surface>
          <max_contacts>10</max_contacts>
        </collision>
        <visual name='back_wheel_L_1_visual'>
          <pose>0.9 -0.6 -0.195 0 -0 0</pose>
          <geometry>
            <mesh>
              <scale>0.001 0.001 0.001</scale>
              <uri>/home/deepak/catkin_ws/src/garbage_robot_description/meshes/back_wheel_L_1.stl</uri>
            </mesh>
          </geometry>
          <material>
            <script>
              <name>Gazebo/Black</name>
              <uri>file://media/materials/scripts/gazebo.material</uri>
            </script>
          </material>
        </visual>
        <self_collide>1</self_collide>
        <enable_wind>0</enable_wind>
        <kinematic>0</kinematic>
      </link>
      <joint name='back_right_joint' type='revolute'>
        <pose relative_to='base_footprint'>-0.9 -0.6 0.195 0 -0 0</pose>
        <parent>base_footprint</parent>
        <child>back_wheel_R_1</child>
        <axis>
          <xyz>0 1 0</xyz>
          <limit>
            <lower>-1e+16</lower>
            <upper>1e+16</upper>
          </limit>
          <dynamics>
            <spring_reference>0</spring_reference>
            <spring_stiffness>0</spring_stiffness>
          </dynamics>
        </axis>
      </joint>
      <link name='back_wheel_R_1'>
        <pose relative_to='back_right_joint'>0 0 0 0 -0 0</pose>
        <inertial>
          <pose>-0 -0.005 0 0 -0 0</pose>
          <mass>48.0694</mass>
          <inertia>
            <ixx>0.430714</ixx>
            <ixy>0</ixy>
            <ixz>0</ixz>
            <iyy>0.78997</iyy>
            <iyz>0</iyz>
            <izz>0.430714</izz>
          </inertia>
        </inertial>
        <collision name='back_wheel_R_1_collision'>
          <pose>0.9 0.6 -0.195 0 -0 0</pose>
          <geometry>
            <mesh>
              <scale>0.001 0.001 0.001</scale>
              <uri>/home/deepak/catkin_ws/src/garbage_robot_description/meshes/back_wheel_R_1.stl</uri>
            </mesh>
          </geometry>
          <surface>
            <contact>
              <ode/>
            </contact>
            <friction>
              <ode>
                <mu>100</mu>
                <mu2>100</mu2>
              </ode>
              <torsional>
                <ode/>
              </torsional>
            </friction>
            <bounce/>
          </surface>
          <max_contacts>10</max_contacts>
        </collision>
        <visual name='back_wheel_R_1_visual'>
          <pose>0.9 0.6 -0.195 0 -0 0</pose>
          <geometry>
            <mesh>
              <scale>0.001 0.001 0.001</scale>
              <uri>/home/deepak/catkin_ws/src/garbage_robot_description/meshes/back_wheel_R_1.stl</uri>
            </mesh>
          </geometry>
          <material>
            <script>
              <name>Gazebo/Black</name>
              <uri>file://media/materials/scripts/gazebo.material</uri>
            </script>
          </material>
        </visual>
        <self_collide>1</self_collide>
        <enable_wind>0</enable_wind>
        <kinematic>0</kinematic>
      </link>
      <joint name='left_knuckle' type='revolute'>
        <pose relative_to='base_footprint'>0.945 0.52 0.285 0 -0 0</pose>
        <parent>base_footprint</parent>
        <child>knuckle_left_1</child>
        <axis>
          <xyz>0 0 1</xyz>
          <limit>
            <lower>-0.523599</lower>
            <upper>0.523599</upper>
            <effort>100</effort>
            <velocity>100</velocity>
          </limit>
          <dynamics>
            <spring_reference>0</spring_reference>
            <spring_stiffness>0</spring_stiffness>
          </dynamics>
        </axis>
      </joint>
      <link name='knuckle_left_1'>
        <pose relative_to='left_knuckle'>0 0 0 0 -0 0</pose>
        <inertial>
          <pose>0.00997 0.038218 -0.08 0 -0 0</pose>
          <mass>0.868877</mass>
          <inertia>
            <ixx>0.004488</ixx>
            <ixy>0.000333</ixy>
            <ixz>0</ixz>
            <iyy>0.003619</iyy>
            <iyz>0</iyz>
            <izz>0.001801</izz>
          </inertia>
        </inertial>
        <collision name='knuckle_left_1_collision'>
          <pose>-0.945 -0.52 -0.285 0 -0 0</pose>
          <geometry>
            <mesh>
              <scale>0.001 0.001 0.001</scale>
              <uri>/home/deepak/catkin_ws/src/garbage_robot_description/meshes/knuckle_left_1.stl</uri>
            </mesh>
          </geometry>
          <surface>
            <contact>
              <ode/>
            </contact>
            <friction>
              <ode>
                <mu>0.1</mu>
                <mu2>0.1</mu2>
              </ode>
              <torsional>
                <ode/>
              </torsional>
            </friction>
            <bounce/>
          </surface>
          <max_contacts>10</max_contacts>
        </collision>
        <visual name='knuckle_left_1_visual'>
          <pose>-0.945 -0.52 -0.285 0 -0 0</pose>
          <geometry>
            <mesh>
              <scale>0.001 0.001 0.001</scale>
              <uri>/home/deepak/catkin_ws/src/garbage_robot_description/meshes/knuckle_left_1.stl</uri>
            </mesh>
          </geometry>
          <material>
            <script>
              <name>Gazebo/Green</name>
              <uri>file://media/materials/scripts/gazebo.material</uri>
            </script>
          </material>
        </visual>
        <self_collide>1</self_collide>
        <enable_wind>0</enable_wind>
        <kinematic>0</kinematic>
      </link>
      <joint name='front_left_wheel_joint' type='revolute'>
        <pose relative_to='knuckle_left_1'>1e-05 0.096 -0.08 0 -0 0</pose>
        <parent>knuckle_left_1</parent>
        <child>front_wheel_L_1</child>
        <axis>
          <xyz>0 1 0</xyz>
          <limit>
            <lower>-1e+16</lower>
            <upper>1e+16</upper>
          </limit>
          <dynamics>
            <spring_reference>0</spring_reference>
            <spring_stiffness>0</spring_stiffness>
          </dynamics>
        </axis>
      </joint>
      <link name='front_wheel_L_1'>
        <pose relative_to='front_left_wheel_joint'>0 0 0 0 -0 0</pose>
        <inertial>
          <pose>-0 0.005 0 0 -0 0</pose>
          <mass>48.0694</mass>
          <inertia>
            <ixx>0.430714</ixx>
            <ixy>0</ixy>
            <ixz>0</ixz>
            <iyy>0.78997</iyy>
            <iyz>0</iyz>
            <izz>0.430714</izz>
          </inertia>
        </inertial>
        <collision name='front_wheel_L_1_collision'>
          <pose>-0.94501 -0.616 -0.205 0 -0 0</pose>
          <geometry>
            <mesh>
              <scale>0.001 0.001 0.001</scale>
              <uri>/home/deepak/catkin_ws/src/garbage_robot_description/meshes/front_wheel_L_1.stl</uri>
            </mesh>
          </geometry>
          <surface>
            <contact>
              <ode/>
            </contact>
            <friction>
              <ode>
                <mu>0.1</mu>
                <mu2>0.1</mu2>
              </ode>
              <torsional>
                <ode/>
              </torsional>
            </friction>
            <bounce/>
          </surface>
          <max_contacts>10</max_contacts>
        </collision>
        <visual name='front_wheel_L_1_visual'>
          <pose>-0.94501 -0.616 -0.205 0 -0 0</pose>
          <geometry>
            <mesh>
              <scale>0.001 0.001 0.001</scale>
              <uri>/home/deepak/catkin_ws/src/garbage_robot_description/meshes/front_wheel_L_1.stl</uri>
            </mesh>
          </geometry>
          <material>
            <script>
              <name>Gazebo/Black</name>
              <uri>file://media/materials/scripts/gazebo.material</uri>
            </script>
          </material>
        </visual>
        <self_collide>1</self_collide>
        <enable_wind>0</enable_wind>
        <kinematic>0</kinematic>
      </link>
      <joint name='lidar_joint' type='revolute'>
        <pose relative_to='base_footprint'>1.15 0 0.4 0 -0 0</pose>
        <parent>base_footprint</parent>
        <child>lidar_1</child>
        <axis>
          <xyz>0 1 0</xyz>
          <limit>
            <lower>-0.523</lower>
            <upper>0.523</upper>
            <effort>10</effort>
            <velocity>1</velocity>
          </limit>
          <dynamics>
            <spring_reference>0</spring_reference>
            <spring_stiffness>0</spring_stiffness>
          </dynamics>
        </axis>
      </joint>
      <link name='lidar_1'>
        <pose relative_to='lidar_joint'>0 0 0 0 -0 0</pose>
        <inertial>
          <pose>-0 0 0.023498 0 -0 0</pose>
          <mass>0.231834</mass>
          <inertia>
            <ixx>0.000132</ixx>
            <ixy>0</ixy>
            <ixz>0</ixz>
            <iyy>0.000132</iyy>
            <iyz>0</iyz>
            <izz>0.000169</izz>
          </inertia>
        </inertial>
        <collision name='lidar_1_collision'>
          <pose>-1.01 0 -1.07 0 -0 0</pose>
          <geometry>
            <mesh>
              <scale>0.001 0.001 0.001</scale>
              <uri>/home/deepak/catkin_ws/src/garbage_robot_description/meshes/lidar_1.stl</uri>
            </mesh>
          </geometry>
          <surface>
            <contact>
              <ode/>
            </contact>
            <friction>
              <ode>
                <mu>0.2</mu>
                <mu2>0.2</mu2>
              </ode>
              <torsional>
                <ode/>
              </torsional>
            </friction>
            <bounce/>
          </surface>
          <max_contacts>10</max_contacts>
        </collision>
        <visual name='lidar_1_visual'>
          <pose>-1.01 0 -1.07 0 -0 0</pose>
          <geometry>
            <mesh>
              <scale>0.001 0.001 0.001</scale>
              <uri>/home/deepak/catkin_ws/src/garbage_robot_description/meshes/lidar_1.stl</uri>
            </mesh>
          </geometry>
          <material>
            <script>
              <name>Gazebo/BlueLase</name>
              <uri>file://media/materials/scripts/gazebo.material</uri>
            </script>
          </material>
        </visual>
        <sensor name='head_hokuyo_sensor' type='gpu_ray'>
          <pose>0 0 0 0 -0 0</pose>
          <visualize>1</visualize>
          <update_rate>40</update_rate>
          <ray>
            <scan>
              <horizontal>
                <samples>720</samples>
                <resolution>1</resolution>
                <min_angle>-1.5708</min_angle>
                <max_angle>1.5708</max_angle>
              </horizontal>
              <vertical>
                <samples>1</samples>
                <min_angle>0</min_angle>
                <max_angle>0</max_angle>
              </vertical>
            </scan>
            <range>
              <min>0.1</min>
              <max>12</max>
              <resolution>0.01</resolution>
            </range>
            <noise>
              <type>gaussian</type>
              <mean>0</mean>
              <stddev>0.01</stddev>
            </noise>
          </ray>
          <plugin name='gazebo_ros_head_hokuyo_controller' filename='libgazebo_ros_gpu_laser.so'>
            <topicName>/laser/scan</topicName>
            <frameName>lidar_1</frameName>
            <robotNamespace>/</robotNamespace>
          </plugin>
        </sensor>
        <self_collide>1</self_collide>
        <enable_wind>0</enable_wind>
        <kinematic>0</kinematic>
      </link>
      <joint name='right_knuckle' type='revolute'>
        <pose relative_to='base_footprint'>0.945 -0.52 0.285 0 -0 0</pose>
        <parent>base_footprint</parent>
        <child>knuckle_right_1</child>
        <axis>
          <xyz>0 0 1</xyz>
          <limit>
            <lower>-0.523599</lower>
            <upper>0.523599</upper>
            <effort>100</effort>
            <velocity>100</velocity>
          </limit>
          <dynamics>
            <spring_reference>0</spring_reference>
            <spring_stiffness>0</spring_stiffness>
          </dynamics>
        </axis>
      </joint>
      <link name='knuckle_right_1'>
        <pose relative_to='right_knuckle'>0 0 0 0 -0 0</pose>
        <inertial>
          <pose>0.010539 -0.037865 -0.080731 0 -0 0</pose>
          <mass>0.877201</mass>
          <inertia>
            <ixx>0.004548</ixx>
            <ixy>-0.000351</ixy>
            <ixz>3.8e-05</ixz>
            <iyy>0.003698</iyy>
            <iyz>2.4e-05</iyz>
            <izz>0.001842</izz>
          </inertia>
        </inertial>
        <collision name='knuckle_right_1_collision'>
          <pose>-0.945 0.52 -0.285 0 -0 0</pose>
          <geometry>
            <mesh>
              <scale>0.001 0.001 0.001</scale>
              <uri>/home/deepak/catkin_ws/src/garbage_robot_description/meshes/knuckle_right_1.stl</uri>
            </mesh>
          </geometry>
          <surface>
            <contact>
              <ode/>
            </contact>
            <friction>
              <ode>
                <mu>0.1</mu>
                <mu2>0.1</mu2>
              </ode>
              <torsional>
                <ode/>
              </torsional>
            </friction>
            <bounce/>
          </surface>
          <max_contacts>10</max_contacts>
        </collision>
        <visual name='knuckle_right_1_visual'>
          <pose>-0.945 0.52 -0.285 0 -0 0</pose>
          <geometry>
            <mesh>
              <scale>0.001 0.001 0.001</scale>
              <uri>/home/deepak/catkin_ws/src/garbage_robot_description/meshes/knuckle_right_1.stl</uri>
            </mesh>
          </geometry>
          <material>
            <script>
              <name>Gazebo/Green</name>
              <uri>file://media/materials/scripts/gazebo.material</uri>
            </script>
          </material>
        </visual>
        <self_collide>1</self_collide>
        <enable_wind>0</enable_wind>
        <kinematic>0</kinematic>
      </link>
      <joint name='front_right_wheel_joint' type='revolute'>
        <pose relative_to='knuckle_right_1'>1e-05 -0.096 -0.08 0 -0 0</pose>
        <parent>knuckle_right_1</parent>
        <child>front_wheel_R_1</child>
        <axis>
          <xyz>0 1 0</xyz>
          <limit>
            <lower>-1e+16</lower>
            <upper>1e+16</upper>
          </limit>
          <dynamics>
            <spring_reference>0</spring_reference>
            <spring_stiffness>0</spring_stiffness>
          </dynamics>
        </axis>
      </joint>
      <link name='front_wheel_R_1'>
        <pose relative_to='front_right_wheel_joint'>0 0 0 0 -0 0</pose>
        <inertial>
          <pose>-0 -0.005 0 0 -0 0</pose>
          <mass>48.0694</mass>
          <inertia>
            <ixx>0.430714</ixx>
            <ixy>0</ixy>
            <ixz>0</ixz>
            <iyy>0.78997</iyy>
            <iyz>0</iyz>
            <izz>0.430714</izz>
          </inertia>
        </inertial>
        <collision name='front_wheel_R_1_collision'>
          <pose>-0.94501 0.616 -0.205 0 -0 0</pose>
          <geometry>
            <mesh>
              <scale>0.001 0.001 0.001</scale>
              <uri>/home/deepak/catkin_ws/src/garbage_robot_description/meshes/front_wheel_R_1.stl</uri>
            </mesh>
          </geometry>
          <surface>
            <contact>
              <ode/>
            </contact>
            <friction>
              <ode>
                <mu>0.1</mu>
                <mu2>0.1</mu2>
              </ode>
              <torsional>
                <ode/>
              </torsional>
            </friction>
            <bounce/>
          </surface>
          <max_contacts>10</max_contacts>
        </collision>
        <visual name='front_wheel_R_1_visual'>
          <pose>-0.94501 0.616 -0.205 0 -0 0</pose>
          <geometry>
            <mesh>
              <scale>0.001 0.001 0.001</scale>
              <uri>/home/deepak/catkin_ws/src/garbage_robot_description/meshes/front_wheel_R_1.stl</uri>
            </mesh>
          </geometry>
          <material>
            <script>
              <name>Gazebo/Black</name>
              <uri>file://media/materials/scripts/gazebo.material</uri>
            </script>
          </material>
        </visual>
        <self_collide>1</self_collide>
        <enable_wind>0</enable_wind>
        <kinematic>0</kinematic>
      </link>
      <plugin name='control' filename='libgazebo_ros_control.so'>
        <robotNamespace>/</robotNamespace>
      </plugin>
      <static>0</static>
      <plugin name='differential_drive_controller' filename='libgazebo_ros_diff_drive.so'>
        <robotNamespace>/</robotNamespace>
        <updateRate>10</updateRate>
        <leftJoint>back_right_joint</leftJoint>
        <rightJoint>back_left_joint</rightJoint>
        <wheelSeparation>1.2</wheelSeparation>
        <wheelDiameter>0.330</wheelDiameter>
        <wheelAcceleration>1.0</wheelAcceleration>
        <wheelTorque>20</wheelTorque>
        <commandTopic>cmd_vel</commandTopic>
        <odometryTopic>odom</odometryTopic>
        <odometryFrame>odom</odometryFrame>
        <robotBaseFrame>base_footprint</robotBaseFrame>
        <odometrySource>1</odometrySource>
        <publishOdomTF>1</publishOdomTF>
        <publishWheelTF>1</publishWheelTF>
        <publishOdom>1</publishOdom>
        <publishWheelJointState>1</publishWheelJointState>
        <legacyMode>0</legacyMode>
      </plugin>
      <pose>0 0 0 0 -0 0</pose>
    </model>
    <model name='Campus'>
      <static>1</static>
      <link name='floor_1'>
        <visual name='visual'>
          <pose>0 0 -0.25 0 -0 0</pose>
          <geometry>
            <mesh>
              <uri>https://fuel.ignitionrobotics.org/1.0/ncs_robotmanager/models/campus/1/files/meshes/Campus_world.obj</uri>
            </mesh>
          </geometry>
        </visual>
        <collision name='collision'>
          <pose>0 0 -0.25 0 -0 0</pose>
          <geometry>
            <mesh>
              <uri>https://fuel.ignitionrobotics.org/1.0/ncs_robotmanager/models/campus/1/files/meshes/Campus_world.obj</uri>
            </mesh>
          </geometry>
          <max_contacts>10</max_contacts>
          <surface>
            <contact>
              <ode/>
            </contact>
            <bounce/>
            <friction>
              <torsional>
                <ode/>
              </torsional>
              <ode/>
            </friction>
          </surface>
        </collision>
        <self_collide>0</self_collide>
        <enable_wind>0</enable_wind>
        <kinematic>0</kinematic>
      </link>
      <pose>-56.7353 -9.82965 0 0 -0 0</pose>
    </model>
    <state world_name='default'>
      <sim_time>0 0</sim_time>
      <real_time>0 0</real_time>
      <wall_time>1645254374 176440156</wall_time>
      <iterations>0</iterations>
      <model name='Campus'>
        <pose>-56.7353 -9.82965 0 0 -0 0</pose>
        <scale>1 1 1</scale>
        <link name='floor_1'>
          <pose>-56.7353 -9.82965 0 0 -0 0</pose>
          <velocity>0 0 0 0 -0 0</velocity>
          <acceleration>0 0 0 0 -0 0</acceleration>
          <wrench>0 0 0 0 -0 0</wrench>
        </link>
      </model>
      <model name='garbage_robot'>
        <pose>0 0 0 0 -0 0</pose>
        <scale>1 1 1</scale>
        <link name='LINK2_1'>
          <pose>0.57 0.305 0.756 0 -0 0</pose>
          <velocity>0 0 0 0 -0 0</velocity>
          <acceleration>0 0 0 0 -0 0</acceleration>
          <wrench>0 0 0 0 -0 0</wrench>
        </link>
        <link name='back_wheel_L_1'>
          <pose>-0.9 0.6 0.195 0 -0 0</pose>
          <velocity>0 0 0 0 -0 0</velocity>
          <acceleration>0 0 0 0 -0 0</acceleration>
          <wrench>0 0 0 0 -0 0</wrench>
        </link>
        <link name='back_wheel_R_1'>
          <pose>-0.9 -0.6 0.195 0 -0 0</pose>
          <velocity>0 0 0 0 -0 0</velocity>
          <acceleration>0 0 0 0 -0 0</acceleration>
          <wrench>0 0 0 0 -0 0</wrench>
        </link>
        <link name='base_footprint'>
          <pose>0 0 0 0 -0 0</pose>
          <velocity>0 0 0 0 -0 0</velocity>
          <acceleration>0 0 0 0 -0 0</acceleration>
          <wrench>0 0 0 0 -0 0</wrench>
        </link>
        <link name='front_wheel_L_1'>
          <pose>0.94501 0.616 0.205 0 -0 0</pose>
          <velocity>0 0 0 0 -0 0</velocity>
          <acceleration>0 0 0 0 -0 0</acceleration>
          <wrench>0 0 0 0 -0 0</wrench>
        </link>
        <link name='front_wheel_R_1'>
          <pose>0.94501 -0.616 0.205 0 -0 0</pose>
          <velocity>0 0 0 0 -0 0</velocity>
          <acceleration>0 0 0 0 -0 0</acceleration>
          <wrench>0 0 0 0 -0 0</wrench>
        </link>
        <link name='gripper1_1'>
          <pose>-0.051 0.56 0.281 0 -0 0</pose>
          <velocity>0 0 0 0 -0 0</velocity>
          <acceleration>0 0 0 0 -0 0</acceleration>
          <wrench>0 0 0 0 -0 0</wrench>
        </link>
        <link name='gripper2_1'>
          <pose>-0.051 0.56 0.261 0 -0 0</pose>
          <velocity>0 0 0 0 -0 0</velocity>
          <acceleration>0 0 0 0 -0 0</acceleration>
          <wrench>0 0 0 0 -0 0</wrench>
        </link>
        <link name='knuckle_left_1'>
          <pose>0.945 0.52 0.285 0 -0 0</pose>
          <velocity>0 0 0 0 -0 0</velocity>
          <acceleration>0 0 0 0 -0 0</acceleration>
          <wrench>0 0 0 0 -0 0</wrench>
        </link>
        <link name='knuckle_right_1'>
          <pose>0.945 -0.52 0.285 0 -0 0</pose>
          <velocity>0 0 0 0 -0 0</velocity>
          <acceleration>0 0 0 0 -0 0</acceleration>
          <wrench>0 0 0 0 -0 0</wrench>
        </link>
        <link name='lidar_1'>
          <pose>1.15 0 0.4 0 -0 0</pose>
          <velocity>0 0 0 0 -0 0</velocity>
          <acceleration>0 0 0 0 -0 0</acceleration>
          <wrench>0 0 0 0 -0 0</wrench>
        </link>
        <link name='link1_1'>
          <pose>-0.35 0.1 0.945 0 -0 0</pose>
          <velocity>0 0 0 0 -0 0</velocity>
          <acceleration>0 0 0 0 -0 0</acceleration>
          <wrench>0 0 0 0 -0 0</wrench>
        </link>
      </model>
      <light name='sun'>
        <pose>0 0 10 0 -0 0</pose>
      </light>
    </state>
    <gui fullscreen='0'>
      <camera name='user_camera'>
        <pose>168.206 -106.348 58.5986 0 0.275643 2.35619</pose>
        <view_controller>orbit</view_controller>
        <projection_type>perspective</projection_type>
      </camera>
    </gui>
  </world>
</sdf>
