<?xml version="1.0" ?>
<robot name="garbage_robot" xmlns:xacro="http://www.ros.org/wiki/xacro">

<xacro:include filename="$(find garbage_robot_description)/urdf/materials.xacro" />
<xacro:include filename="$(find garbage_robot_description)/urdf/garbage_robot.trans" />
<xacro:include filename="$(find garbage_robot_description)/urdf/garbage_robot.gazebo" />
<!--<link name="base_footprint" />
    <joint name="dummy_joint" type="fixed">
        <origin rpy="0 0 0" xyz="0.0 0.0 0.0" />
        <parent link="base_footprint" />
        <child link="base_link" />
    </joint> -->
<link name="base_link">
  <inertial>
    <origin rpy="0 0 0" xyz="0.38482610777733756 0.0031040430443198147 0.3998905084334025"/>
    <mass value="223.35773084869004"/>
    <inertia ixx="40.549749" ixy="-0.114517" ixz="-13.629602" iyy="99.249109" iyz="-0.360598" izz="110.698343"/>
  </inertial>
  <visual>
    <origin rpy="0 0 0" xyz="0 0 0"/>
    <geometry>
      <mesh filename="package://garbage_robot_description/meshes/base_link.stl" scale="0.001 0.001 0.001"/>
    </geometry>
    <material name="red"/>
  </visual>
  <collision>
    <origin rpy="0 0 0" xyz="0 0 0"/>
    <geometry>
      <mesh filename="package://garbage_robot_description/meshes/base_link.stl" scale="0.001 0.001 0.001"/>
    </geometry>
  </collision>
</link>

<link name="back_wheel_R_1">
  <inertial>
    <origin rpy="0 0 0" xyz="-8.548717289613705e-15 -0.0050000000000000044 2.7755575615628914e-17"/>
    <mass value="48.069415006398515"/>
    <inertia ixx="0.430714" ixy="0.0" ixz="0.0" iyy="0.78997" iyz="-0.0" izz="0.430714"/>
  </inertial>
  <visual>
    <origin rpy="0 0 0" xyz="0.9 0.6 -0.195"/>
    <geometry>
      <mesh filename="package://garbage_robot_description/meshes/back_wheel_R_1.stl" scale="0.001 0.001 0.001"/>
    </geometry>
    <material name="black"/>
  </visual>
  <collision>
    <origin rpy="0 0 0" xyz="0.9 0.6 -0.195"/>
    <geometry>
      <mesh filename="package://garbage_robot_description/meshes/back_wheel_R_1.stl" scale="0.001 0.001 0.001"/>
    </geometry>
  </collision>
</link>

<link name="back_wheel_L_1">
  <inertial>
    <origin rpy="0 0 0" xyz="-8.548717289613705e-15 0.0050000000000000044 2.7755575615628914e-17"/>
    <mass value="48.069415006398515"/>
    <inertia ixx="0.430714" ixy="-0.0" ixz="0.0" iyy="0.78997" iyz="0.0" izz="0.430714"/>
  </inertial>
  <visual>
    <origin rpy="0 0 0" xyz="0.9 -0.6 -0.195"/>
    <geometry>
      <mesh filename="package://garbage_robot_description/meshes/back_wheel_L_1.stl" scale="0.001 0.001 0.001"/>
    </geometry>
    <material name="black"/>
  </visual>
  <collision>
    <origin rpy="0 0 0" xyz="0.9 -0.6 -0.195"/>
    <geometry>
      <mesh filename="package://garbage_robot_description/meshes/back_wheel_L_1.stl" scale="0.001 0.001 0.001"/>
    </geometry>
  </collision>
</link>

<link name="knuckle_right_1">
  <inertial>
    <origin rpy="0 0 0" xyz="0.010539451692655244 -0.037865406760327236 -0.08073060915094679"/>
    <mass value="0.87720060854411"/>
    <inertia ixx="0.004548" ixy="-0.000351" ixz="3.8e-05" iyy="0.003698" iyz="2.4e-05" izz="0.001842"/>
  </inertial>
  <visual>
    <origin rpy="0 0 0" xyz="-0.945 0.52 -0.285"/>
    <geometry>
      <mesh filename="package://garbage_robot_description/meshes/knuckle_right_1.stl" scale="0.001 0.001 0.001"/>
    </geometry>
    <material name="silver"/>
  </visual>
  <collision>
    <origin rpy="0 0 0" xyz="-0.945 0.52 -0.285"/>
    <geometry>
      <mesh filename="package://garbage_robot_description/meshes/knuckle_right_1.stl" scale="0.001 0.001 0.001"/>
    </geometry>
  </collision>
</link>

<link name="knuckle_left_1">
  <inertial>
    <origin rpy="0 0 0" xyz="0.009969859878305343 0.03821839597067289 -0.0799999999999999"/>
    <mass value="0.8688773515075006"/>
    <inertia ixx="0.004488" ixy="0.000333" ixz="-0.0" iyy="0.003619" iyz="0.0" izz="0.001801"/>
  </inertial>
  <visual>
    <origin rpy="0 0 0" xyz="-0.945 -0.52 -0.285"/>
    <geometry>
      <mesh filename="package://garbage_robot_description/meshes/knuckle_left_1.stl" scale="0.001 0.001 0.001"/>
    </geometry>
    <material name="silver"/>
  </visual>
  <collision>
    <origin rpy="0 0 0" xyz="-0.945 -0.52 -0.285"/>
    <geometry>
      <mesh filename="package://garbage_robot_description/meshes/knuckle_left_1.stl" scale="0.001 0.001 0.001"/>
    </geometry>
  </collision>
</link>

<link name="front_wheel_R_1">
  <inertial>
    <origin rpy="0 0 0" xyz="-4.942435471999573e-07 -0.0050000000000000044 2.220446049250313e-16"/>
    <mass value="48.069415006398515"/>
    <inertia ixx="0.430714" ixy="0.0" ixz="0.0" iyy="0.78997" iyz="0.0" izz="0.430714"/>
  </inertial>
  <visual>
    <origin rpy="0 0 0" xyz="-0.94501 0.616 -0.205"/>
    <geometry>
      <mesh filename="package://garbage_robot_description/meshes/front_wheel_R_1.stl" scale="0.001 0.001 0.001"/>
    </geometry>
    <material name="black"/>
  </visual>
  <collision>
    <origin rpy="0 0 0" xyz="-0.94501 0.616 -0.205"/>
    <geometry>
      <mesh filename="package://garbage_robot_description/meshes/front_wheel_R_1.stl" scale="0.001 0.001 0.001"/>
    </geometry>
  </collision>
</link>

<link name="front_wheel_L_1">
  <inertial>
    <origin rpy="0 0 0" xyz="-4.942435471999573e-07 0.0050000000000000044 5.551115123125783e-17"/>
    <mass value="48.069415006398515"/>
    <inertia ixx="0.430714" ixy="0.0" ixz="0.0" iyy="0.78997" iyz="0.0" izz="0.430714"/>
  </inertial>
  <visual>
    <origin rpy="0 0 0" xyz="-0.94501 -0.616 -0.205"/>
    <geometry>
      <mesh filename="package://garbage_robot_description/meshes/front_wheel_L_1.stl" scale="0.001 0.001 0.001"/>
    </geometry>
    <material name="black"/>
  </visual>
  <collision>
    <origin rpy="0 0 0" xyz="-0.94501 -0.616 -0.205"/>
    <geometry>
      <mesh filename="package://garbage_robot_description/meshes/front_wheel_L_1.stl" scale="0.001 0.001 0.001"/>
    </geometry>
  </collision>
</link>

<link name="link1_1">
  <inertial>
    <origin rpy="0 0 0" xyz="0.8999999999999999 0.0820028216111279 -0.12641985967462654"/>
    <mass value="2.146073295804804"/>
    <inertia ixx="0.018306" ixy="0.0" ixz="0.0" iyy="0.011609" iyz="0.00497" izz="0.007961"/>
  </inertial>
  <visual>
    <origin rpy="0 0 0" xyz="0.35 -0.1 -0.945"/>
    <geometry>
      <mesh filename="package://garbage_robot_description/meshes/link1_1.stl" scale="0.001 0.001 0.001"/>
    </geometry>
    <material name="silver"/>
  </visual>
  <collision>
    <origin rpy="0 0 0" xyz="0.35 -0.1 -0.945"/>
    <geometry>
      <mesh filename="package://garbage_robot_description/meshes/link1_1.stl" scale="0.001 0.001 0.001"/>
    </geometry>
  </collision>
</link>

<link name="LINK2_1">
  <inertial>
    <origin rpy="0 0 0" xyz="-0.10694805745507208 0.10992529567155457 -0.36171686512141704"/>
    <mass value="4.1711800597770425"/>
    <inertia ixx="0.144545" ixy="0.052615" ixz="-0.035282" iyy="0.209347" iyz="0.044606" izz="0.175506"/>
  </inertial>
  <visual>
    <origin rpy="0 0 0" xyz="-0.57 -0.305 -0.756"/>
    <geometry>
      <mesh filename="package://garbage_robot_description/meshes/LINK2_1.stl" scale="0.001 0.001 0.001"/>
    </geometry>
    <material name="silver"/>
  </visual>
  <collision>
    <origin rpy="0 0 0" xyz="-0.57 -0.305 -0.756"/>
    <geometry>
      <mesh filename="package://garbage_robot_description/meshes/LINK2_1.stl" scale="0.001 0.001 0.001"/>
    </geometry>
  </collision>
</link>

<link name="gripper1_1">
  <inertial>
    <origin rpy="0 0 0" xyz="0.25866397128286994 0.010473831160217162 -0.0050000000000000044"/>
    <mass value="1.7962228903755257"/>
    <inertia ixx="0.003042" ixy="-0.005052" ixz="0.0" iyy="0.040386" iyz="0.0" izz="0.043398"/>
  </inertial>
  <visual>
    <origin rpy="0 0 0" xyz="0.051 -0.56 -0.281"/>
    <geometry>
      <mesh filename="package://garbage_robot_description/meshes/gripper1_1.stl" scale="0.001 0.001 0.001"/>
    </geometry>
    <material name="silver"/>
  </visual>
  <collision>
    <origin rpy="0 0 0" xyz="0.051 -0.56 -0.281"/>
    <geometry>
      <mesh filename="package://garbage_robot_description/meshes/gripper1_1.stl" scale="0.001 0.001 0.001"/>
    </geometry>
  </collision>
</link>

<link name="container_1">
  <inertial>
    <origin rpy="0 0 0" xyz="1.5912718697858623 0.49300000000000277 0.20230925694218077"/>
    <mass value="22.181481802688776"/>
    <inertia ixx="3.924176" ixy="0.0" ixz="-0.277567" iyy="5.8003" iyz="0.0" izz="8.221847"/>
  </inertial>
  <visual>
    <origin rpy="0 0 0" xyz="1.955 0.493 -0.435"/>
    <geometry>
      <mesh filename="package://garbage_robot_description/meshes/container_1.stl" scale="0.001 0.001 0.001"/>
    </geometry>
    <material name="green"/>
  </visual>
  <collision>
    <origin rpy="0 0 0" xyz="1.955 0.493 -0.435"/>
    <geometry>
      <mesh filename="package://garbage_robot_description/meshes/container_1.stl" scale="0.001 0.001 0.001"/>
    </geometry>
  </collision>
</link>

<link name="lidar_1">
  <inertial>
    <origin rpy="0 0 0" xyz="-8.881784197001252e-16 0.0 0.023497521162210377"/>
    <mass value="0.2318339515171583"/>
    <inertia ixx="0.000132" ixy="-0.0" ixz="-0.0" iyy="0.000132" iyz="0.0" izz="0.000169"/>
  </inertial>
  <visual>
    <origin rpy="0 0 0" xyz="-1.01 -0.0 -1.07"/>
    <geometry>
      <mesh filename="package://garbage_robot_description/meshes/lidar_1.stl" scale="0.001 0.001 0.001"/>
    </geometry>
    <material name="blue"/>
  </visual>
  <collision>
    <origin rpy="0 0 0" xyz="-1.01 -0.0 -1.07"/>
    <geometry>
      <mesh filename="package://garbage_robot_description/meshes/lidar_1.stl" scale="0.001 0.001 0.001"/>
    </geometry>
  </collision>
</link>

<link name="front_cam_1">
  <inertial>
    <origin rpy="0 0 0" xyz="0.8700000000000001 0.0 0.02499999999999991"/>
    <mass value="0.1325"/>
    <inertia ixx="5.5e-05" ixy="-0.0" ixz="0.0" iyy="5.5e-05" iyz="0.0" izz="5.5e-05"/>
  </inertial>
  <visual>
    <origin rpy="0 0 0" xyz="-0.21 -0.0 -1.0"/>
    <geometry>
      <mesh filename="package://garbage_robot_description/meshes/front_cam_1.stl" scale="0.001 0.001 0.001"/>
    </geometry>
    <material name="silver"/>
  </visual>
  <collision>
    <origin rpy="0 0 0" xyz="-0.21 -0.0 -1.0"/>
    <geometry>
      <mesh filename="package://garbage_robot_description/meshes/front_cam_1.stl" scale="0.001 0.001 0.001"/>
    </geometry>
  </collision>
</link>

<link name="side_cam_1">
  <inertial>
    <origin rpy="0 0 0" xyz="0.8999999999999998 0.025000000000000022 -0.15000000000000002"/>
    <mass value="0.98125"/>
    <inertia ixx="0.000409" ixy="-0.0" ixz="0.0" iyy="0.000409" iyz="0.0" izz="0.000409"/>
  </inertial>
  <visual>
    <origin rpy="0 0 0" xyz="-0.01 -0.5 -0.65"/>
    <geometry>
      <mesh filename="package://garbage_robot_description/meshes/side_cam_1.stl" scale="0.001 0.001 0.001"/>
    </geometry>
    <material name="silver"/>
  </visual>
  <collision>
    <origin rpy="0 0 0" xyz="-0.01 -0.5 -0.65"/>
    <geometry>
      <mesh filename="package://garbage_robot_description/meshes/side_cam_1.stl" scale="0.001 0.001 0.001"/>
    </geometry>
  </collision>
</link>

<link name="gripper2_1">
  <inertial>
    <origin rpy="0 0 0" xyz="-0.25866397128287033 0.010473831160217162 -0.005000000000000171"/>
    <mass value="1.7962228903755257"/>
    <inertia ixx="0.003042" ixy="0.005052" ixz="0.0" iyy="0.040386" iyz="-0.0" izz="0.043398"/>
  </inertial>
  <visual>
    <origin rpy="0 0 0" xyz="0.051 -0.56 -0.281"/>
    <geometry>
      <mesh filename="package://garbage_robot_description/meshes/gripper2_1.stl" scale="0.001 0.001 0.001"/>
    </geometry>
    <material name="silver"/>
  </visual>
  <collision>
    <origin rpy="0 0 0" xyz="0.051 -0.56 -0.281"/>
    <geometry>
      <mesh filename="package://garbage_robot_description/meshes/gripper2_1.stl" scale="0.001 0.001 0.001"/>
    </geometry>
  </collision>
</link>
<link name="imu_link_1">
  <inertial>
    <origin rpy="0 0 0" xyz="0.0 0.0 0.0050000000000000044"/>
    <mass value="0.0265"/>
    <inertia ixx="6e-06" ixy="0.0" ixz="0.0" iyy="6e-06" iyz="0.0" izz="1.1e-05"/>
  </inertial>
  <visual>
    <origin rpy="0 0 0" xyz="-0.435 -0.0 -0.255"/>
    <geometry>
      <mesh filename="package://garbage_robot_description/meshes/imu_link_1.stl" scale="0.001 0.001 0.001"/>
    </geometry>
    <material name="silver"/>
  </visual>
  <collision>
    <origin rpy="0 0 0" xyz="-0.435 -0.0 -0.255"/>
    <geometry>
      <mesh filename="package://garbage_robot_description/meshes/imu_link_1.stl" scale="0.001 0.001 0.001"/>
    </geometry>
  </collision>
</link>
<joint name="back_right_joint" type="continuous">
  <origin rpy="0 0 0" xyz="-0.9 -0.6 0.195"/>
  <parent link="base_link"/>
  <child link="back_wheel_R_1"/>
  <axis xyz="0.0 1.0 0.0"/>
</joint>

<joint name="back_left_joint" type="continuous">
  <origin rpy="0 0 0" xyz="-0.9 0.6 0.195"/>
  <parent link="base_link"/>
  <child link="back_wheel_L_1"/>
  <axis xyz="0.0 1.0 0.0"/>
</joint>

<joint name="right_knuckle" type="revolute">
  <origin rpy="0 0 0" xyz="0.945 -0.52 0.285"/>
  <parent link="base_link"/>
  <child link="knuckle_right_1"/>
  <axis xyz="-0.0 0.0 1.0"/>
  <limit effort="100" lower="-0.523599" upper="0.523599" velocity="100"/>
</joint>

<joint name="left_knuckle" type="revolute">
  <origin rpy="0 0 0" xyz="0.945 0.52 0.285"/>
  <parent link="base_link"/>
  <child link="knuckle_left_1"/>
  <axis xyz="0.0 0.0 1.0"/>
  <limit effort="100" lower="-0.523599" upper="0.523599" velocity="100"/>
</joint>

<joint name="front_right_wheel_joint" type="continuous">
  <origin rpy="0 0 0" xyz="1e-05 -0.096 -0.08"/>
  <parent link="knuckle_right_1"/>
  <child link="front_wheel_R_1"/>
  <axis xyz="0.0 1.0 0.0"/>
</joint>

<joint name="front_left_wheel_joint" type="continuous">
  <origin rpy="0 0 0" xyz="1e-05 0.096 -0.08"/>
  <parent link="knuckle_left_1"/>
  <child link="front_wheel_L_1"/>
  <axis xyz="0.0 1.0 0.0"/>
</joint>

<joint name="Slider" type="prismatic">
  <origin rpy="0 0 0" xyz="-0.35 0.1 0.945"/>
  <parent link="base_link"/>
  <child link="link1_1"/>
  <axis xyz="0.0 1.0 0.0"/>
  <limit effort="100" lower="0.0" upper="0.3" velocity="0.5"/>
</joint>

<joint name="arm_joint" type="revolute">
  <origin rpy="0 0 0" xyz="0.92 0.205 -0.189"/>
  <parent link="link1_1"/>
  <child link="LINK2_1"/>
  <axis xyz="1.0 -0.0 0.0"/>
  <limit effort="100" lower="-3.14" upper="3.14" velocity="0.5"/>
</joint>

<joint name="gripper1_joint" type="revolute">
  <origin rpy="0 0 0" xyz="-0.621 0.255 -0.475"/>
  <parent link="LINK2_1"/>
  <child link="gripper1_1"/>
  <axis xyz="0.0 0.0 -1.0"/>
  <limit effort="100" lower="-3.14" upper="3.14" velocity="0.5"/>
</joint>

<joint name="tipper_joint" type="fixed">
  <origin rpy="0 0 0" xyz="-1.955 -0.493 0.435"/>
  <parent link="base_link"/>
  <child link="container_1"/>
</joint>
<!--
  <joint name="tipper_joint" type="continuous">
  <origin rpy="0 0 0" xyz="-1.955 -0.493 0.435"/>
  <parent link="base_link"/>
  <child link="container_1"/>
  <axis xyz="0.0 1.0 0.0"/>
</joint>
-->
<!--<joint name="lidar_joint" type="revolute">
  <origin rpy="0 0 0" xyz="1.15 0.0 1.2"/>
  <parent link="base_link"/>
  <child link="lidar_1"/>
  <axis xyz="0.0 1.0 0.0"/>
  <limit effort="10" lower="-0.523" upper="0.523" velocity="1"/>
</joint>-->
<joint name="lidar_joint" type="fixed">
  <origin rpy="0 0 0" xyz="1.15 0.0 1.2"/>
  <parent link="base_link"/>
  <child link="lidar_1"/>
</joint>

<joint name="front_cam_joint" type="fixed">
  <origin rpy="0 0 0" xyz="0.21 0.0 1.0"/>
  <parent link="base_link"/>
  <child link="front_cam_1"/>
</joint>

<joint name="side_cam_joint" type="fixed">
  <origin rpy="0 0 0" xyz="0.01 0.5 0.65"/>
  <parent link="base_link"/>
  <child link="side_cam_1"/>
</joint>

<joint name="gripper2_joint" type="revolute">
  <origin rpy="0 0 0" xyz="-0.621 0.255 -0.495"/>
  <parent link="LINK2_1"/>
  <child link="gripper2_1"/>
  <axis xyz ="-0.0 0.0 -1.0"/>
  <limit effort="100" lower="-3.14" upper="3.14" velocity="0.5"/>
</joint>
<joint name="imu_joint" type="fixed">
  <origin rpy="0 0 0" xyz="0.435 0.0 0.255"/>
  <parent link="base_link"/>
  <child link="imu_link_1"/>
</joint>

</robot>
